<?xml version="1.0" encoding="UTF-8"?>
<!-- Generated by org.testng.reporters.JUnitXMLReporter -->
<testsuite ignored="0" hostname="FleetStudio-21" failures="1" tests="3" name="Test" time="14.458" errors="0" timestamp="2023-02-27T21:26:12 IST">
  <testcase classname="fleetwally.wally.ErrorMessageValidation" name="LoginApplication" time="0.369"/>
  <testcase classname="fleetwally.wally.ErrorMessageValidation" name="LoginErrorMessage" time="1.345"/>
  <testcase classname="fleetwally.wally.ErrorMessageValidation" name="LoginErrorMessage" time="1.385">
    <failure type="java.lang.AssertionError" message="expected [User does not exist.] but found [Incorrect Credentials. Please try again]">
      <![CDATA[java.lang.AssertionError: expected [User does not exist.] but found [Incorrect Credentials. Please try again]
at fleetwally.wally.ErrorMessageValidation.LoginErrorMessage(ErrorMessageValidation.java:23)
at java.base/java.util.ArrayList.forEach(ArrayList.java:1511)
... Removed 33 stack frames]]>
    </failure>
  </testcase> <!-- LoginErrorMessage -->
</testsuite> <!-- Test -->
