<?xml version="1.0" encoding="UTF-8"?>
<testng-results ignored="0" total="4" passed="2" failed="2" skipped="0">
  <reporter-output>
  </reporter-output>
  <suite started-at="2023-03-06T13:27:32 IST" name="WallySuite" finished-at="2023-03-06T13:27:54 IST" duration-ms="21619">
    <groups>
    </groups>
    <test started-at="2023-03-06T13:27:32 IST" name="Test" finished-at="2023-03-06T13:27:54 IST" duration-ms="21619">
      <class name="fleetwally.wally.LoginValidation">
        <test-method is-config="true" signature="launchApplication()[pri:0, instance:fleetwally.wally.LoginValidation@2b30a42c]" started-at="2023-03-06T13:27:32 IST" name="launchApplication" finished-at="2023-03-06T13:27:38 IST" duration-ms="5201" status="PASS">
          <reporter-output>
          </reporter-output>
        </test-method> <!-- launchApplication -->
        <test-method signature="LoginApplication()[pri:0, instance:fleetwally.wally.LoginValidation@2b30a42c]" started-at="2023-03-06T13:27:38 IST" name="LoginApplication" finished-at="2023-03-06T13:27:38 IST" duration-ms="535" status="PASS">
          <reporter-output>
          </reporter-output>
        </test-method> <!-- LoginApplication -->
        <test-method is-config="true" signature="closeBrowser()[pri:0, instance:fleetwally.wally.LoginValidation@2b30a42c]" started-at="2023-03-06T13:27:38 IST" name="closeBrowser" finished-at="2023-03-06T13:27:38 IST" duration-ms="229" status="PASS">
          <reporter-output>
          </reporter-output>
        </test-method> <!-- closeBrowser -->
        <test-method is-config="true" signature="launchApplication()[pri:0, instance:fleetwally.wally.LoginValidation@2b30a42c]" started-at="2023-03-06T13:27:38 IST" name="launchApplication" finished-at="2023-03-06T13:27:41 IST" duration-ms="2858" status="PASS">
          <reporter-output>
          </reporter-output>
        </test-method> <!-- launchApplication -->
        <test-method signature="LoginErrorMessage(java.util.HashMap)[pri:0, instance:fleetwally.wally.LoginValidation@2b30a42c]" started-at="2023-03-06T13:27:41 IST" name="LoginErrorMessage" data-provider="hashmapdata" finished-at="2023-03-06T13:27:43 IST" duration-ms="1352" status="PASS">
          <params>
            <param index="0">
              <value>
                <![CDATA[{pass=Hanmant@12345, Email=hpawar@fleetstudio.com}]]>
              </value>
            </param>
          </params>
          <reporter-output>
          </reporter-output>
        </test-method> <!-- LoginErrorMessage -->
        <test-method is-config="true" signature="closeBrowser()[pri:0, instance:fleetwally.wally.LoginValidation@2b30a42c]" started-at="2023-03-06T13:27:43 IST" name="closeBrowser" finished-at="2023-03-06T13:27:43 IST" duration-ms="160" status="PASS">
          <reporter-output>
          </reporter-output>
        </test-method> <!-- closeBrowser -->
        <test-method is-config="true" signature="launchApplication()[pri:0, instance:fleetwally.wally.LoginValidation@2b30a42c]" started-at="2023-03-06T13:27:43 IST" name="launchApplication" finished-at="2023-03-06T13:27:47 IST" duration-ms="3954" status="PASS">
          <reporter-output>
          </reporter-output>
        </test-method> <!-- launchApplication -->
        <test-method signature="LoginErrorMessage(java.util.HashMap)[pri:0, instance:fleetwally.wally.LoginValidation@2b30a42c]" started-at="2023-03-06T13:27:47 IST" name="LoginErrorMessage" data-provider="hashmapdata" finished-at="2023-03-06T13:27:48 IST" duration-ms="1363" status="FAIL">
          <params>
            <param index="0">
              <value>
                <![CDATA[{pass=Hanmant@369, Email=hanmant@fleetstudio.com}]]>
              </value>
            </param>
          </params>
          <exception class="java.lang.AssertionError">
            <message>
              <![CDATA[expected [User does not exist.] but found [Incorrect Credentials. Please try again]]]>
            </message>
            <full-stacktrace>
              <![CDATA[java.lang.AssertionError: expected [User does not exist.] but found [Incorrect Credentials. Please try again]
at org.testng.Assert.fail(Assert.java:99)
at org.testng.Assert.failNotEquals(Assert.java:1037)
at org.testng.Assert.assertEqualsImpl(Assert.java:140)
at org.testng.Assert.assertEquals(Assert.java:122)
at org.testng.Assert.assertEquals(Assert.java:629)
at org.testng.Assert.assertEquals(Assert.java:639)
at fleetwally.wally.LoginValidation.LoginErrorMessage(LoginValidation.java:29)
at java.base/jdk.internal.reflect.NativeMethodAccessorImpl.invoke0(Native Method)
at java.base/jdk.internal.reflect.NativeMethodAccessorImpl.invoke(NativeMethodAccessorImpl.java:77)
at java.base/jdk.internal.reflect.DelegatingMethodAccessorImpl.invoke(DelegatingMethodAccessorImpl.java:43)
at java.base/java.lang.reflect.Method.invoke(Method.java:568)
at org.testng.internal.MethodInvocationHelper.invokeMethod(MethodInvocationHelper.java:133)
at org.testng.internal.TestInvoker.invokeMethod(TestInvoker.java:598)
at org.testng.internal.TestInvoker.invokeTestMethod(TestInvoker.java:173)
at org.testng.internal.MethodRunner.runInSequence(MethodRunner.java:46)
at org.testng.internal.TestInvoker$MethodInvocationAgent.invoke(TestInvoker.java:824)
at org.testng.internal.TestInvoker.invokeTestMethods(TestInvoker.java:146)
at org.testng.internal.TestMethodWorker.invokeTestMethods(TestMethodWorker.java:146)
at org.testng.internal.TestMethodWorker.run(TestMethodWorker.java:128)
at java.base/java.util.ArrayList.forEach(ArrayList.java:1511)
at org.testng.TestRunner.privateRun(TestRunner.java:794)
at org.testng.TestRunner.run(TestRunner.java:596)
at org.testng.SuiteRunner.runTest(SuiteRunner.java:377)
at org.testng.SuiteRunner.runSequentially(SuiteRunner.java:371)
at org.testng.SuiteRunner.privateRun(SuiteRunner.java:332)
at org.testng.SuiteRunner.run(SuiteRunner.java:276)
at org.testng.SuiteRunnerWorker.runSuite(SuiteRunnerWorker.java:53)
at org.testng.SuiteRunnerWorker.run(SuiteRunnerWorker.java:96)
at org.testng.TestNG.runSuitesSequentially(TestNG.java:1212)
at org.testng.TestNG.runSuitesLocally(TestNG.java:1134)
at org.testng.TestNG.runSuites(TestNG.java:1063)
at org.testng.TestNG.run(TestNG.java:1031)
at org.testng.remote.AbstractRemoteTestNG.run(AbstractRemoteTestNG.java:115)
at org.testng.remote.RemoteTestNG.initAndRun(RemoteTestNG.java:251)
at org.testng.remote.RemoteTestNG.main(RemoteTestNG.java:77)
]]>
            </full-stacktrace>
          </exception> <!-- java.lang.AssertionError -->
          <reporter-output>
          </reporter-output>
        </test-method> <!-- LoginErrorMessage -->
        <test-method is-config="true" signature="closeBrowser()[pri:0, instance:fleetwally.wally.LoginValidation@2b30a42c]" started-at="2023-03-06T13:27:48 IST" name="closeBrowser" finished-at="2023-03-06T13:27:48 IST" duration-ms="153" status="PASS">
          <reporter-output>
          </reporter-output>
        </test-method> <!-- closeBrowser -->
        <test-method is-config="true" signature="launchApplication()[pri:0, instance:fleetwally.wally.LoginValidation@2b30a42c]" started-at="2023-03-06T13:27:48 IST" name="launchApplication" finished-at="2023-03-06T13:27:52 IST" duration-ms="4035" status="PASS">
          <reporter-output>
          </reporter-output>
        </test-method> <!-- launchApplication -->
        <test-method signature="LoginErrorMessage(java.util.HashMap)[pri:0, instance:fleetwally.wally.LoginValidation@2b30a42c]" started-at="2023-03-06T13:27:52 IST" name="LoginErrorMessage" data-provider="hashmapdata" finished-at="2023-03-06T13:27:54 IST" duration-ms="1321" status="FAIL">
          <params>
            <param index="0">
              <value>
                <![CDATA[{pass=vipul@23651, Email=vipul@fleetstudio.com}]]>
              </value>
            </param>
          </params>
          <exception class="java.lang.AssertionError">
            <message>
              <![CDATA[expected [User does not exist.] but found [Incorrect Credentials. Please try again]]]>
            </message>
            <full-stacktrace>
              <![CDATA[java.lang.AssertionError: expected [User does not exist.] but found [Incorrect Credentials. Please try again]
at org.testng.Assert.fail(Assert.java:99)
at org.testng.Assert.failNotEquals(Assert.java:1037)
at org.testng.Assert.assertEqualsImpl(Assert.java:140)
at org.testng.Assert.assertEquals(Assert.java:122)
at org.testng.Assert.assertEquals(Assert.java:629)
at org.testng.Assert.assertEquals(Assert.java:639)
at fleetwally.wally.LoginValidation.LoginErrorMessage(LoginValidation.java:29)
at java.base/jdk.internal.reflect.NativeMethodAccessorImpl.invoke0(Native Method)
at java.base/jdk.internal.reflect.NativeMethodAccessorImpl.invoke(NativeMethodAccessorImpl.java:77)
at java.base/jdk.internal.reflect.DelegatingMethodAccessorImpl.invoke(DelegatingMethodAccessorImpl.java:43)
at java.base/java.lang.reflect.Method.invoke(Method.java:568)
at org.testng.internal.MethodInvocationHelper.invokeMethod(MethodInvocationHelper.java:133)
at org.testng.internal.TestInvoker.invokeMethod(TestInvoker.java:598)
at org.testng.internal.TestInvoker.invokeTestMethod(TestInvoker.java:173)
at org.testng.internal.MethodRunner.runInSequence(MethodRunner.java:46)
at org.testng.internal.TestInvoker$MethodInvocationAgent.invoke(TestInvoker.java:824)
at org.testng.internal.TestInvoker.invokeTestMethods(TestInvoker.java:146)
at org.testng.internal.TestMethodWorker.invokeTestMethods(TestMethodWorker.java:146)
at org.testng.internal.TestMethodWorker.run(TestMethodWorker.java:128)
at java.base/java.util.ArrayList.forEach(ArrayList.java:1511)
at org.testng.TestRunner.privateRun(TestRunner.java:794)
at org.testng.TestRunner.run(TestRunner.java:596)
at org.testng.SuiteRunner.runTest(SuiteRunner.java:377)
at org.testng.SuiteRunner.runSequentially(SuiteRunner.java:371)
at org.testng.SuiteRunner.privateRun(SuiteRunner.java:332)
at org.testng.SuiteRunner.run(SuiteRunner.java:276)
at org.testng.SuiteRunnerWorker.runSuite(SuiteRunnerWorker.java:53)
at org.testng.SuiteRunnerWorker.run(SuiteRunnerWorker.java:96)
at org.testng.TestNG.runSuitesSequentially(TestNG.java:1212)
at org.testng.TestNG.runSuitesLocally(TestNG.java:1134)
at org.testng.TestNG.runSuites(TestNG.java:1063)
at org.testng.TestNG.run(TestNG.java:1031)
at org.testng.remote.AbstractRemoteTestNG.run(AbstractRemoteTestNG.java:115)
at org.testng.remote.RemoteTestNG.initAndRun(RemoteTestNG.java:251)
at org.testng.remote.RemoteTestNG.main(RemoteTestNG.java:77)
]]>
            </full-stacktrace>
          </exception> <!-- java.lang.AssertionError -->
          <reporter-output>
          </reporter-output>
        </test-method> <!-- LoginErrorMessage -->
        <test-method is-config="true" signature="closeBrowser()[pri:0, instance:fleetwally.wally.LoginValidation@2b30a42c]" started-at="2023-03-06T13:27:54 IST" name="closeBrowser" finished-at="2023-03-06T13:27:54 IST" duration-ms="141" status="PASS">
          <reporter-output>
          </reporter-output>
        </test-method> <!-- closeBrowser -->
      </class> <!-- fleetwally.wally.LoginValidation -->
    </test> <!-- Test -->
  </suite> <!-- WallySuite -->
</testng-results>
